<?xml version="1.0"?>

<robot xmlns:xacro="http://www.ros.org/wiki/xacro" 
 	xmlns:sensor="http://playerstage.sourceforge.net/gazebo/xmlschema/#sensor"
    	xmlns:controller="http://playerstage.sourceforge.net/gazebo/xmlschema/#controller"
    	xmlns:interface="http://playerstage.sourceforge.net/gazebo/xmlschema/#interface"
	name="robot_car">




	<xacro:property name="length_wheel" value="0.03" />
	<xacro:property name="radius_wheel" value="0.075" />
	<xacro:property name="rplidar_link" value="0.05" />
	<!--xacro:include filename="$(find myrobot)/robot_description/urdf/robot.gazebo" /-->
	<xacro:macro name="default_inertial" params="mass">
               <inertial>
                       <mass value="${mass}" />
                       <inertia ixx="1.0" ixy="0.0" ixz="0.0"
                                iyy="1.0" iyz="0.0"
                                izz="1.0" />
               </inertial>
	</xacro:macro>
	
	<link name="base_link">
   		<visual>
			<geometry>
      				<box size="0.52 .38 0.05"/>
     			</geometry>
			<origin rpy="0 0 0" xyz="0 0 -0.025"/>
			<material name="white">
				<color rgba="1 1 1 1"/>
			</material>
   		</visual>
		<collision>
			<geometry>
       				<box size="0.52 .38 0.05"/>
			</geometry>
		</collision>
		<xacro:default_inertial mass="5"/>
 	</link>
		<gazebo reference="base_link">
			<turnGravityOff>false</turnGravityOff>
		</gazebo>

	<link name="layer1">
   		<visual>
			<geometry>
      				<box size="0.2 .16 0.01"/>
     			</geometry>
			<origin rpy="0 0 0" xyz="0 0 0.005"/>
			<material name="white">
				<color rgba="1 1 1 1"/>
			</material>
   		</visual>
		<collision>
			<geometry>
       				<box size="0.2 .16 0.01"/>
			</geometry>
		</collision>
		<xacro:default_inertial mass="2"/>
 	</link>

     	<link name="layer2">
   		<visual>
			<geometry>
      				<box size="0.056 .08 0.01"/>
     			</geometry>
			<origin rpy="0 0 0" xyz="0 0 0.005"/>
			<material name="white">
				<color rgba="1 1 1 1"/>
			</material>
   		</visual>
		<collision>
			<geometry>
       				<box size="0.056 .08 0.01"/>
			</geometry>
		</collision>
		<xacro:default_inertial mass="1"/>
 	</link>

<link name="wheel_1">
   		<visual>
     			<geometry>
       				<cylinder length="${length_wheel}" radius="${radius_wheel}"/>
     			</geometry>
			<!-- <origin rpy="0 1.5 0" xyz="0.1 0.1 0"/> -->
			<origin rpy="0 0 0" xyz="0 0 0"/>
   			<material name="black">
				<color rgba="0 0 0 1"/>
			</material>
		</visual>
		<collision>
			<geometry>
       				<cylinder length="${length_wheel}" radius="${radius_wheel}"/>
			</geometry>
		</collision>
		<xacro:default_inertial mass="1"/>
 	</link>

 	<link name="wheel_2">
   		<visual>
     			<geometry>
       				<cylinder length="${length_wheel}" radius="${radius_wheel}"/>
     			</geometry>
			<!-- <origin rpy="0 1.5 0" xyz="-0.1 0.1 0"/> -->
			<origin rpy="0 0 0" xyz="0 0 0"/>
   			<material name="black"/>
   		</visual>
		<collision>
			<geometry>
       				<cylinder length="${length_wheel}" radius="${radius_wheel}"/>
			</geometry>
		</collision>
		<xacro:default_inertial mass="1"/>

 	</link>
    
 	<link name="wheel_3">
   		<visual>
     			<geometry>
       				<cylinder length="${length_wheel}" radius="${radius_wheel}"/>
     			</geometry>
			<!-- <origin rpy="0 1.5 0" xyz="0.1 -0.1 0"/> -->

			<origin rpy="0 0 0" xyz="0 0 0"/>
   			<material name="black"/>
   		</visual>
		<collision>
			<geometry>
       				<cylinder length="${length_wheel}" radius="${radius_wheel}"/>
			</geometry>
		</collision>
		<xacro:default_inertial mass="1"/>
 	</link>

 	<link name="wheel_4">
   		<visual>
     			<geometry>
       				<cylinder length="${length_wheel}" radius="${radius_wheel}"/>
     			</geometry>
		<!--	<origin rpy="0 1.5 0" xyz="-0.1 -0.1 0"/> -->
			<origin rpy="0 0 0" xyz="0 0 0" />
   			<material name="black"/>
   		</visual>
		<collision>
			<geometry>
       				<cylinder length="${length_wheel}" radius="${radius_wheel}"/>
			</geometry>
		</collision>
		<xacro:default_inertial mass="1"/>

 	</link>

  <joint name="layer1" type="fixed">
    <axis xyz="0 1 0" />
    <origin xyz="0.05 0 0.2" rpy="0 0 0"/>
    <parent link="base_link"/>
    <child link="layer1"/>
  </joint>

    <joint name="layer2" type="fixed">
    <axis xyz="0 1 0" />
    <origin xyz="0.0 0 0.26" rpy="0 0 0"/>
    <parent link="base_link"/>
    <child link="layer2"/>
  </joint>

 <joint name="base_to_wheel1" type="continuous">
   <parent link="base_link"/>
   <child link="wheel_1"/>
   <origin rpy="-1.5707 0 0" xyz="0.192 0.215 0"/>
   <axis xyz="0 0 0.016" />
 </joint>

 <joint name="base_to_wheel2" type="continuous">
   <axis xyz="0 0 1" />
   <anchor xyz="0 0 0" />
   <limit effort="100" velocity="100" />
   <parent link="base_link"/>
   <child link="wheel_2"/>
   <origin rpy="-1.5707 0 0" xyz="0.192 -0.215 0"/>
</joint>

 <joint name="base_to_wheel3" type="continuous">
   <parent link="base_link"/>
   <axis xyz="0 0 1" />
   <child link="wheel_3"/>
   <origin rpy="-1.5707 0 0" xyz="-0.19 0.215 0"/>
 </joint>

 <joint name="base_to_wheel4" type="continuous">
   <parent link="base_link"/>
   <axis xyz="0 0 1" />
   <child link="wheel_4"/>
   <origin rpy="-1.5707 0 0" xyz="-0.19 -0.215 0"/>
 </joint>
 <!-- Camera joint -->
  <joint name="camera_joint" type="fixed">
    <axis xyz="0 1 0" />
    <origin xyz="0 0 0.286" rpy="0 0 0"/>
    <parent link="base_link"/>
    <child link="camera_link"/>
  </joint>

  <!-- Camera -->
  <link name="camera_link">
    <collision>
      <origin xyz="0 0 0" rpy="0 0 0"/>
      <geometry>
	<box size="0.05 0.05 0.05"/>
      </geometry>
    </collision>

    <visual>
      <origin xyz="0 0 0" rpy="0 0 0"/>
      <geometry>
	<box size="0.05 0.05 0.05"/>
      </geometry>
      <material name="red">
	<color rgba="1 0 0 1"/>
      </material>
    </visual>

    <inertial>
      <mass value="1e-5" />
      <origin xyz="0 0 0" rpy="0 0 0"/>
      <inertia ixx="1e-6" ixy="0" ixz="0" iyy="1e-6" iyz="0" izz="1e-6" />
    </inertial>
</link>

<!-- rplidar joint -->
  <joint name="rplidar_joint" type="fixed">
    <origin xyz="0.05 0 0.201" rpy="0 0 3.1415"/>
    <parent link="base_link"/>
    <child link="rplidar_link"/>
  </joint>
<!-- rplidar Laser -->
  <link name="rplidar_link">
    <collision>
      <origin xyz="0 0 0.031" rpy="0 0 0"/>
        <geometry>
	              <cylinder length="0.041" radius="0.0378"/>
        </geometry>
    </collision>
    <visual>
      <origin xyz="0 0 0.031" rpy="0 0 0"/>
        <geometry>
	              <cylinder length="0.041" radius="0.0378"/>
        </geometry>

    </visual>

    <inertial>
      <mass value="1e-5" />
      <origin xyz="0 0 0" rpy="0 0 0"/>
      <inertia ixx="1e-6" ixy="0" ixz="0" iyy="1e-6" iyz="0" izz="1e-6" />
    </inertial>
  </link>

  <!-- Drive controller -->
<gazebo>
  <plugin name="skid_steer_drive_controller" filename="libgazebo_ros_skid_steer_drive.so">
    <updateRate>30.0</updateRate>
    <robotNamespace>/</robotNamespace>
    <leftFrontJoint>base_to_wheel1</leftFrontJoint>
    <rightFrontJoint>base_to_wheel2</rightFrontJoint>
    <leftRearJoint>base_to_wheel3</leftRearJoint>
    <rightRearJoint>base_to_wheel4</rightRearJoint>
    <wheelSeparation>5</wheelSeparation>
    <wheelDiameter>0.15</wheelDiameter>
    <robotBaseFrame>base_link</robotBaseFrame>
    <odometryFrame>odom</odometryFrame>
		<odometryTopic>odom</odometryTopic>
    <torque>2</torque>
    <commandTopic>cmd_vel</commandTopic>
    <broadcastTF>1</broadcastTF>
  </plugin>
</gazebo>


</robot>